Workbook

Sheet Comparable Companies
A1: 北京航天驭星科技 (AEROSPACE YUXING) — COMPARABLE COMPANY ANALYSIS
A2: Ground segment: 星图测控 (920116.BJ) · Kratos (KTOS) · Gilat (GILT) · Comtech (CMTL) · KSAT (private) | Satellite operators / broad space: Iridium (IRDM) · Viasat (VSAT) · SES (SESG.PA) · Globalstar (GSAT) · Rocket Lab (RKLB)
A3: Model date: 13-Jun-2026 | Figures USD millions except ratios & per-share | LTM / latest FY | BLUE = hardcoded input (see cell comment for source/confidence) · BLACK = formula
A5: Company | B5: Ticker / Status | C5: Tier | D5: Revenue (LTM, $mm) | E5: Rev Growth YoY % | F5: Gross Margin % | G5: EBITDA ($mm) | H5: EBITDA Margin % | I5: Net Income ($mm) | J5: Market Cap ($mm) | K5: Net Debt ($mm) | L5: Enterprise Value ($mm) | M5: EV / Revenue | N5: EV / EBITDA | O5: P / E
A6: GROUND SEGMENT — TT&C-as-a-service + ground-station / antenna / modem equipment (maps to 航天驭星 Segments 1 & 2)
A7: 星图测控 (STAR.VISION) | B7: 920116.BJ | C7: Ground | D7: 40.3 | E7: 0.258 | F7: 0.528 | G7: 14 | H7: =IF(D7=0,"",G7/D7) | I7: 11.9 | J7: 2084 | K7: -290 | L7: =J7+K7 | M7: =IF(D7=0,"",L7/D7) | N7: =IF(G7>0,L7/G7,"n/m") | O7: =IF(I7>0,J7/I7,"n/m")
A8: Kratos Defense | B8: KTOS | C8: Ground | D8: 1200 | E8: 0.1 | F8: 0.25 | G8: 110 | H8: =IF(D8=0,"",G8/D8) | I8: 40 | J8: 11300 | K8: -100 | L8: =J8+K8 | M8: =IF(D8=0,"",L8/D8) | N8: =IF(G8>0,L8/G8,"n/m") | O8: =IF(I8>0,J8/I8,"n/m")
A9: Gilat Satellite Networks | B9: GILT | C9: Ground | D9: 420 | E9: 0.35 | F9: 0.35 | G9: 55 | H9: =IF(D9=0,"",G9/D9) | I9: 25 | J9: 650 | K9: -60 | L9: =J9+K9 | M9: =IF(D9=0,"",L9/D9) | N9: =IF(G9>0,L9/G9,"n/m") | O9: =IF(I9>0,J9/I9,"n/m")
A10: Comtech Telecom | B10: CMTL | C10: Ground (distressed) | D10: 500 | E10: -0.1 | F10: 0.3 | G10: 20 | H10: =IF(D10=0,"",G10/D10) | I10: -30 | J10: 120 | K10: 250 | L10: =J10+K10 | M10: =IF(D10=0,"",L10/D10) | N10: =IF(G10>0,L10/G10,"n/m") | O10: n/m
A11: KSAT (Kongsberg Sat. Svcs) | B11: Private | C11: Ground (ops only) | D11: 208 | E11: 0.3 | F11: n/a | G11: 35 | H11: =IF(D11=0,"",G11/D11) | I11: n/a | J11: — | K11: — | L11: — | M11: — | N11: — | O11: —
A12: SATELLITE OPERATORS / BROAD SPACE — demand-side context & 'space premium' band (vertically integrated → sanity band, not pure comps)
A13: Iridium Communications | B13: IRDM | C13: Operator | D13: 830 | E13: 0.05 | F13: 0.7 | G13: 465 | H13: =IF(D13=0,"",G13/D13) | I13: 110 | J13: 2900 | K13: 1500 | L13: =J13+K13 | M13: =IF(D13=0,"",L13/D13) | N13: =IF(G13>0,L13/G13,"n/m") | O13: =IF(I13>0,J13/I13,"n/m")
A14: Viasat | B14: VSAT | C14: Operator | D14: 4500 | E14: 0.03 | F14: 0.35 | G14: 1500 | H14: =IF(D14=0,"",G14/D14) | I14: -120 | J14: 3800 | K14: 5700 | L14: =J14+K14 | M14: =IF(D14=0,"",L14/D14) | N14: =IF(G14>0,L14/G14,"n/m") | O14: n/m
A15: SES S.A. | B15: SESG.PA | C15: Operator | D15: 2160 | E15: -0.02 | F15: n/a | G15: 1134 | H15: =IF(D15=0,"",G15/D15) | I15: 90 | J15: 3240 | K15: 3400 | L15: =J15+K15 | M15: =IF(D15=0,"",L15/D15) | N15: =IF(G15>0,L15/G15,"n/m") | O15: =IF(I15>0,J15/I15,"n/m")
A16: Globalstar | B16: GSAT | C16: Operator | D16: 250 | E16: 0.2 | F16: 0.65 | G16: 130 | H16: =IF(D16=0,"",G16/D16) | I16: 5 | J16: 3200 | K16: 300 | L16: =J16+K16 | M16: =IF(D16=0,"",L16/D16) | N16: =IF(G16>0,L16/G16,"n/m") | O16: =IF(I16>0,J16/I16,"n/m")
A17: Rocket Lab | B17: RKLB | C17: Operator (growth) | D17: 530 | E17: 0.3 | F17: 0.28 | G17: -50 | H17: =IF(D17=0,"",G17/D17) | I17: -90 | J17: 20000 | K17: -400 | L17: =J17+K17 | M17: =IF(D17=0,"",L17/D17) | N17: =IF(G17>0,L17/G17,"n/m") | O17: n/m
A19: SECTOR STATISTICS
A20: Maximum | E20: =MAX(E7:E17) | F20: =MAX(F7:F17) | H20: =MAX(H7:H17) | M20: =MAX(M7:M17) | N20: =MAX(N7:N17) | O20: =MAX(O7:O17)
A21: 75th percentile | E21: =QUARTILE(E7:E17,3) | F21: =QUARTILE(F7:F17,3) | H21: =QUARTILE(H7:H17,3) | M21: =QUARTILE(M7:M17,3) | N21: =QUARTILE(N7:N17,3) | O21: =QUARTILE(O7:O17,3)
A22: Median (all w/ data) | E22: =MEDIAN(E7:E17) | F22: =MEDIAN(F7:F17) | H22: =MEDIAN(H7:H17) | M22: =MEDIAN(M7:M17) | N22: =MEDIAN(N7:N17) | O22: =MEDIAN(O7:O17)
A23: 25th percentile | E23: =QUARTILE(E7:E17,1) | F23: =QUARTILE(F7:F17,1) | H23: =QUARTILE(H7:H17,1) | M23: =QUARTILE(M7:M17,1) | N23: =QUARTILE(N7:N17,1) | O23: =QUARTILE(O7:O17,1)
A24: Minimum | E24: =MIN(E7:E17) | F24: =MIN(F7:F17) | H24: =MIN(H7:H17) | M24: =MIN(M7:M17) | N24: =MIN(N7:N17) | O24: =MIN(O7:O17)
A25: Mean | E25: =AVERAGE(E7:E17) | F25: =AVERAGE(F7:F17) | H25: =AVERAGE(H7:H17) | M25: =AVERAGE(M7:M17) | N25: =AVERAGE(N7:N17) | O25: =AVERAGE(O7:O17)
A27: Median — Ground only (R7:R11) | E27: =MEDIAN(E7:E11) | F27: =MEDIAN(F7:F11) | H27: =MEDIAN(H7:H11) | M27: =MEDIAN(M7:M11) | N27: =MEDIAN(N7:N11) | O27: =MEDIAN(O7:O11)
A28: Median — Operators only (R13:R17) | E28: =MEDIAN(E13:E17) | F28: =MEDIAN(F13:F17) | H28: =MEDIAN(H13:H17) | M28: =MEDIAN(M13:M17) | N28: =MEDIAN(N13:N17) | O28: =MEDIAN(O13:O17)
A30: ⚠ Stats note: Comtech (distressed) & Rocket Lab (extreme growth premium) distort percentiles — read them with the ground/operator sub-medians and the Notes tab caveats. KSAT carries no market cap (operating benchmark only).

Sheet Target Revenue Build
A1: 航天驭星 — SEGMENT REVENUE ESTIMATE (bottom-up, ¥ millions)
A2: No disclosed financials (pre-IPO, tutoring filing 05-Jun-2026). Triangulated from public volume hints. ALL figures = ESTIMATES.
A4: Driver / Segment | B4: Unit | C4: Low | D4: Base | E4: High
A5: TT&C SERVICE LINE (recurring, KSAT-like)
A6: TT&C passes 2025E | B6: k 轨次 | C6: 400 | D6: 480 | E6: 600 | F6: ← 翻倍外推: 2022实际6万(36Kr) → 12万 → 24万 → 48万
A7: Revenue per pass | B7: ¥ | C7: 500 | D7: 750 | E7: 1000 | F7: ← Benchmarked: see "Intl Pricing Benchmarks" tab
A8: Service revenue | B8: ¥mm | C8: =C6*C7/1000 | D8: =D6*D7/1000 | E8: =E6*E7/1000
A9: GROUND-STATION EQUIPMENT LINE (project-based, Kratos/Gilat-like)
A10: Equipment revenue 2025E | B10: ¥mm | C10: 200 | D10: 300 | E10: 450
A11: '航天云' DATA LINE (early-stage / optionality)
A12: Data revenue 2025E | B12: ¥mm | C12: 20 | D12: 40 | E12: 80
A14: TOTAL 2025E REVENUE | C14: =C8+C10+C12 | D14: =D8+D10+D12 | E14: =E8+E10+E12
A15: Service mix % | C15: =C8/C14 | D15: =D8/D14 | E15: =E8/E14
A16: Equipment mix % | C16: =C10/C14 | D16: =D10/D14 | E16: =E10/E14
A17: Data mix % | C17: =C12/C14 | D17: =D12/D14 | E17: =E12/E14
A19: FORWARD 2027E REVENUE (GW / 千帆 build → operate inflection)
A20: Service revenue 2027E | B20: ¥mm | C20: 600 | D20: 900 | E20: 1400 | F20: ← 轨次量持续增长 + GW/千帆星座全面部署
A21: Equipment revenue 2027E | B21: ¥mm | C21: 400 | D21: 650 | E21: 1000
A22: Data revenue 2027E | B22: ¥mm | C22: 80 | D22: 180 | E22: 350
A23: TOTAL 2027E REVENUE | C23: =C20+C21+C22 | D23: =D20+D21+D22 | E23: =E20+E21+E22
A25: INTERNATIONAL PRICING CROSS-CHECK
A26: AWS GS S-band reserved (8-min pass) | C26: ¥174/pass | D26: $3/min × 8min × ¥7.25
A27: AWS GS S-band on-demand (8-min pass) | C27: ¥580/pass | D27: $10/min × 8min × ¥7.25
A28: KSAT implied (TT&C-adj., 2024) | C28: ¥710/pass | D28: $210M rev × 70% TT&C / 1.5M passes × ¥7.25
A29: China annual fee implied | C29: ¥650/pass | D29: ¥650,000/sat/yr ÷ 1,000 passes/yr
A30: Base case assumption | C30: ¥750/pass | D30: Within KSAT-implied range, Tier ③ full-service
A31: Status | C31: SUPPORTED | D31: Upgraded from unsupported estimate
A33: VOLUME SOURCING — 翻倍外推法
A34: 年份 | B34: 轨次量 | C34: 来源/依据 | D34: 置信度
A35: 2021 实际 | B35: ~2万轨次 | C35: 36Kr融资报道（硬数据） | D35: HIGH
A36: 2022 实际 | B36: ~6万轨次 | C36: 36Kr融资报道（硬数据） | D36: HIGH
A37: 2023E 外推 | B37: ~12万轨次 | C37: "连续四年翻倍增长"（公司PR/36Kr） | D37: MED
A38: 2024E 外推 | B38: ~24万轨次 | C38: 同上 + 在管卫星360+颗佐证 | D38: MED
A39: 2025E 外推（基准） | B39: ~48万轨次 | C39: 翻倍趋势延续；中国航天市场趋势可能保守 | D39: MED
A41: 交叉验证
A42: 自下而上 | B42: 360颗卫星 × 3次/天 × 365天 = 39.4万 | C42: 框住48万区间
A43: KSAT产能比例 | B43: 航天驭星60站/KSAT 200站 × 150万 = ~45万 | C43: 接近48万
A44: 翻倍趋势 vs 模型 | B44: 48万(翻倍) vs 旧模型32万(弱化25%) | C44: 已修正

Sheet Intl Pricing Benchmarks
A1: INTERNATIONAL TT&C PRICING BENCHMARKS — ANCHORING THE ¥750/PASS ASSUMPTION
A2: Sources: AWS, KSAT annual report, Leaf Space, Frank Rayal GSaaS analysis, industry press. All figures converted at USD/CNY 7.25.
A4: A. CLOUD GROUND STATION PER-MINUTE RATES (pure antenna time, no operations)
A5: Provider | B5: Band / Tier | C5: $/min Reserved | D5: $/min On-Demand | E5: Typical Pass (min) | F5: $/pass Reserved | G5: $/pass On-Demand | H5: ¥/pass On-Demand
A6: AWS Ground Station | B6: Narrowband (<40MHz, S-band TT&C) | C6: 3 | D6: 10 | E6: 8 | F6: =C6*E6 | G6: =D6*E6 | H6: =G6*7.25
A7: AWS Ground Station | B7: Wideband (≥40MHz, X-band data) | C7: 10 | D7: 22 | E7: 8 | F7: =C7*E7 | G7: =D7*E7 | H7: =G7*7.25
A8: Leaf Space | B8: S/X-band all-inclusive | C8: ~3-5 | D8: n/a (per-min only) | E8: 8 | F8: ~24-40 | G8: — | H8: ~174-290
A9: Azure Orbital | B9: Not public (per-min model) | C9: — | D9: — | E9: 8 | F9: — | G9: — | H9: —
A11: Note: AWS = raw antenna time only. No mission planning, scheduling, TT&C operations staff, or data processing. Full-service providers add 2-3x premium.
A13: B. FULL-SERVICE TT&C — IMPLIED PER-PASS ECONOMICS
A14: Provider | B14: Revenue (ann.) | C14: Passes (ann.) | D14: Implied $/pass | E14: Implied ¥/pass | F14: Service Level | G14: Source | H14: Confidence
A15: KSAT (Norway) | B15: $210M (2024) | C15: 1.5M+ (2023) | D15: ~$140 | E15: ~¥1,015 | F15: Full-service + polar premium | G15: Space Norway AR 2024 | H15: High
A16: KSAT (adj. for TT&C only ~70%) | B16: $147M est. | C16: 1.5M+ | D16: ~$98 | E16: ~¥710 | F16: TT&C portion only | G16: Estimated | H16: Medium
A17: Leaf Space | B17: $1.8M est. (pass rev) | C17: 60k (5k/mo) | D17: ~$30 | E17: ~¥218 | F17: Managed GSaaS, smallsat | G17: Company website | H17: Low-Med
A18: Industry benchmark (smallsat) | B18: — | C18: — | D18: $20-80 | E18: ¥145-580 | F18: Basic S-band TT&C | G18: Frank Rayal 2025 | H18: Medium
A19: Industry benchmark (high-link) | B19: — | C19: — | D19: $100-300 | E19: ¥725-2,175 | F19: Full-service, multi-band | G19: Frank Rayal 2025 | H19: Medium
A22: C. CHINA MARKET — PER-SATELLITE ANNUAL SERVICE FEES
A23: Metric | B23: Low | C23: Base | D23: High | E23: Source
A24: Annual TT&C fee per satellite | B24: 500000 | C24: 650000 | D24: 800000 | E24: 未来航天 research (¥60-70万)
A25: Passes per satellite per year | B25: 800 | C25: 1000 | D25: 1200 | E25: Assumes 2-3 contacts/day
A26: Implied ¥/pass | B26: =B24/B25 | C26: =C24/C25 | D26: =D24/D25 | E26: Cross-check
A27: 航天驭星 managed satellites (2025E) | B27: 400 | C27: 450 | D27: 500 | E27: Company PR: 360+ (2024), growing
A28: Implied service revenue (¥M) | B28: =B24*B27/1000000 | C28: =C24*C27/1000000 | D28: =D24*D27/1000000
A31: D. PRICING SPECTRUM — WHERE DOES ¥750/PASS SIT?
A32: Tier | B32: ¥/pass Range | C32: $/pass Range | D32: Typical Provider | E32: Service Scope
A33: ① Raw antenna time (DIY) | B33: ¥174-580 | C33: $24-80 | D33: AWS GS, Azure Orbital | E33: Antenna only, customer operates
A34: ② Managed GSaaS (basic) | B34: ¥145-435 | C34: $20-60 | D34: Leaf Space, RBC Signals | E34: Shared antennas, basic ops
A35: ③ Full-service TT&C (mid) | B35: ¥500-1,000 | C35: $69-138 | D35: 航天驭星 (target zone) | E35: Dedicated ops, mission planning
A36: ④ Premium full-service | B36: ¥1,000-2,175 | C36: $138-300 | D36: KSAT (polar), SSC | E36: Polar coverage, large aperture
A39: E. CONCLUSION & CONFIDENCE ASSESSMENT
A40: • ¥750/pass (base case) sits in Tier ③ "Full-service TT&C" — CONSISTENT with 航天驭星's positioning as a managed service provider with 60+ owned stations.
A41: • Cross-check via per-satellite annual fee: ¥650,000/sat ÷ 1,000 passes/yr = ¥650/pass — within 15% of the ¥750 assumption.
A42: • Cross-check via KSAT implied (adj.): $98/pass × 7.25 = ¥710/pass — within 6% of the ¥750 assumption.
A43: • LOW case ¥500/pass is aggressive — approaches pure DIY/managed GSaaS pricing without accounting for 航天驭星's full-service operations.
A44: • HIGH case ¥1,000/pass is achievable as constellation complexity increases (more debris avoidance, more frequent maneuvers, multi-payload scheduling).
A46: • CONFIDENCE UPGRADE: ¥750/pass moves from "UNSUPPORTED ESTIMATE" to "SUPPORTED BY INTERNATIONAL BENCHMARKS" — still an estimate, but now anchored to:
A47: (1) AWS Ground Station published rates ($3-22/min)
A48: (2) KSAT 2024 implied economics (~$98-140/pass)
A49: (3) China per-satellite annual fee market benchmark (¥60-70万/sat)
A50: (4) Industry pricing spectrum from Frank Rayal GSaaS analysis
...

Sheet Implied Valuation
A1: 航天驭星 — IMPLIED VALUATION (multi-method, ¥ unless noted)
A2: Five independent lenses. No single metric drives the conclusion. ¥mm unless '¥亿' (=¥100mm) noted.
A4: METHOD 1 — SEGMENT-SPLIT EV / SALES (on 2025E base-case revenue)
A5: Segment | B5: 2025E Rev (¥mm) | C5: EV/Sales Low | D5: EV/Sales Base | E5: EV/Sales High | F5: Implied EV Base (¥亿)
A6: Service (TT&C) | B6: ='Target Revenue Build'!D8 | C6: 5 | D6: 8 | E6: 12 | F6: =B6*D6/100
A7: Equipment | B7: ='Target Revenue Build'!D10 | C7: 2 | D7: 3 | E7: 5 | F7: =B7*D7/100
A8: Data (航天云) | B8: ='Target Revenue Build'!D12 | C8: 3 | D8: 4 | E8: 6 | F8: =B8*D8/100
A9: TOTAL implied EV — 2025E | F9: =SUM(F6:F8)
A10: Range (Low → High, ¥亿) | B10: =(B6*C6+B7*C7+B8*C8)/100 | C10: → | D10: =(B6*E6+B7*E7+B8*E8)/100
A12: METHOD 2 — SEGMENT-SPLIT EV / SALES (on 2027E forward revenue, base multiples)
A13: Segment | B13: 2027E Rev (¥mm) | C13: — | D13: EV/Sales Base | E13: — | F13: Implied EV Base (¥亿)
A14: Service | B14: ='Target Revenue Build'!D20 | D14: =D6 | F14: =B14*D14/100
A15: Equipment | B15: ='Target Revenue Build'!D21 | D15: =D7 | F15: =B15*D15/100
A16: Data | B16: ='Target Revenue Build'!D22 | D16: =D8 | F16: =B16*D16/100
A17: TOTAL implied EV — 2027E (undiscounted) | F17: =SUM(F14:F16)
A18: PV of 2027E EV (WACC 14.0%, 2.0 yrs) | B18: 0.13992887 | F18: =F17/(1+B18)^2
A20: METHOD 3 — EV / CAPACITY (ground-station unit economics, KSAT-benchmarked)
A21: Metric | B21: Count | C21: ¥/unit Low (¥亿) | D21: ¥/unit High (¥亿) | E21: — | F21: Implied EV (¥亿)
A22: Ground stations (套) | B22: 60 | C22: 0.36 | D22: 0.71 | F22: =B22*C22
A23: Range (Low → High, ¥亿) | F23: =B22*D22
A24: ⚠ 'station' vs 'antenna' definitions differ across operators; per-station value is indicative only.
A26: METHOD 4 — FUNDING-IMPLIED EV (reverse-engineered from rounds; equity value ≈ EV, minimal net debt)
A27: Round / Mark | B27: Amount raised (¥亿) | C27: Assumed stake % | D27: — | E27: — | F27: Implied post-money (¥亿)
A28: D round (Dec-2025) | B28: 6 | C28: 0.09 | F28: =B28/C28
A29: C+ round (Aug-2025) | B29: 4.3 | C29: 0.08 | F29: =B29/C29
A30: Reported 'unicorn' mark (range) | B30: 60 | C30: → | D30: 70
A33: FOOTBALL FIELD — VALUATION RANGE BY METHOD (¥亿)
A34: Method | B34: Low (¥亿) | C34: High (¥亿) | D34: Midpoint | E34: Confidence | F34: Comment | H34: span
A35: 1. Segment-split EV/Sales — 2025E (current) | B35: =B10 | C35: =D10 | D35: =(B35+C35)/2 | E35: Med | F35: Today's-sales view → looks cheap vs funding mark; credits only build-phase output. | H35: =C35-B35
A36: 2. Segment-split — 2027E forward (undisc.) | B36: =('Target Revenue Build'!D20*C6+'Target Revenue Build'!D21*C7+'Target Revenue Build'!D22*C8)/100 | C36: =('Target Revenue Build'!D20*E6+'Target Revenue Build'!D21*E7+'Target Revenue Build'!D22*E8)/100 | D36: =(B36+C36)/2 | E36: Low | F36: Forward view → reconciles toward funding mark; the bull case. | H36: =C36-B36
A37: 2b. Segment-split — 2027E forward (PV @ WACC 14.0%) | B37: =B36/(1+B18)^2 | C37: =C36/(1+B18)^2 | D37: =(B37+C37)/2 | E37: Med | F37: WACC-derived (was 20% ad-hoc). See WACC Analysis tab. | H37: =C37-B37
A38: 3. EV / Capacity (per station) | B38: =F22 | C38: =F23 | D38: =(B38+C38)/2 | E38: Low | F38: Double-estimate (KSAT EV est.); sanity band only. | H38: =C38-B38
A39: 4. Funding-implied / unicorn mark | B39: =MIN(F28:F29,B30) | C39: =MAX(F28:F29,D30) | D39: =(B39+C39)/2 | E39: High | F39: What the last private rounds actually priced. | H39: =C39-B39
A41: CONCLUDED FAIR-VALUE RANGE (today) | B41: 48 | C41: 72 | D41: =(B41+C41)/2 | F41: ← Updated: volume adjusted to doubling trend (48万/yr base)

Sheet Unit Economics
A1: 航天驭星 — UNIT ECONOMICS (TT&C service line; supporting pillar for comps)
A2: Capacity-infra model, NOT SaaS. Analogs: satellite pass = usage unit · ground station = capacity/asset unit · satellite operator = customer · in-orbit life = contract life. ALL figures = ESTIMATES (no disclosure); KSAT-benchmarked.
A3: Metric | B3: Unit | C3: Current / Base | D3: Mature / full util
A4: A — STATION-LEVEL ECONOMICS (the capacity / asset unit)
A5: Ground stations (套) | B5: # | C5: 60
A6: Annual TT&C service revenue | B6: ¥mm | C6: ='Target Revenue Build'!D8
A7: Revenue per station | B7: ¥mm | C7: =C6/C5
A8: TT&C passes (2025E) | B8: k 轨次 | C8: ='Target Revenue Build'!D6
A9: Passes per station / yr | B9: # | C9: =C8*1000/C5
A10: Passes per station / day | B10: # | C10: =C9/365
A11: Theoretical max passes / station / day | B11: # | C11: 40
A12: Station utilization % | B12: % | C12: =C10/C11
A13: Implied revenue / station at 100% util | B13: ¥mm | C13: =C7/C12
A15: Capex per station | B15: ¥mm | C15: 15
A16: Total network capex (implied) | B16: ¥mm | C16: =C5*C15
A17: Station contribution margin % | B17: % | C17: 0.6
A18: Contribution per station — current | B18: ¥mm | C18: =C7*C17
A19: Simple payback — current util | B19: yrs | C19: =C15/C18
A20: Contribution per station — full util | B20: ¥mm | C20: =C13*C17
A21: Simple payback — full util | B21: yrs | C21: =C15/C20
A22: Pre-tax ROIC — current util | B22: % | C22: =C18/C15
A23: Pre-tax ROIC — full util | B23: % | C23: =C20/C15
A25: B — PASS-LEVEL ECONOMICS (the usage unit → marginal economics)
A26: Revenue per pass | B26: ¥ | C26: ='Target Revenue Build'!D7
A27: Marginal cost per pass | B27: ¥ | C27: 100
A28: Contribution per pass | B28: ¥ | C28: =C26-C27
A29: Incremental contribution margin % | B29: % | C29: =C28/C26
A31: C — PER-SATELLITE 'CUSTOMER' LTV
A32: Annual active satellites under service | B32: # | C32: 400 | D32: ← 公司PR: 360+颗(2024)，持续增长
A33: Passes per satellite / yr | B33: # | C33: =C8*1000/C32
A34: ARPU per satellite / yr | B34: ¥mm | C34: =C6/C32
A35: Avg in-orbit service life | B35: yrs | C35: 5
A36: Service gross contribution margin % | B36: % | C36: 0.7
A37: LTV per satellite (undiscounted) | B37: ¥mm | C37: =C34*C35*C36
A38: Discount rate | B38: % | C38: 0.15
A39: LTV per satellite (PV) | B39: ¥mm | C39: =C34*C36*(1-(1+C38)^(-C35))/C38
A40: CAC per satellite (onboarding) | B40: ¥mm | C40: 0.2
A41: LTV / CAC (undiscounted) | B41: x | C41: =C37/C40
A42: LTV / CAC (PV) | B42: x | C42: =C39/C40
A44: D — RETENTION & REVENUE QUALITY
...

Sheet WACC Analysis
A1: 航天驭星 — WACC ANALYSIS
A2: Replaces 20% ad-hoc with fundamentally derived WACC from comparable companies.
A3: BLUE = hardcoded input · BLACK = formula · GREEN = concluded output
A5: STEP 1 — UNLEVERED BETA FROM COMPS
A6: β_unlevered = β_levered / [1 + (1 − Tax) × (D / E)] | D/E uses Net Debt (floored at 0, i.e. net-cash firms → D/E = 0)
A8: Company | B8: Ticker | C8: β Levered (5Y) | D8: Mkt Cap ($mm) | E8: Net Debt ($mm) | F8: D/E | G8: Tax Rate | H8: β Unlevered
A9: — GROUND SEGMENT —
A10: Kratos Defense | B10: KTOS | C10: 1.06 | D10: 11300 | E10: -100 | F10: 0 | G10: 0.21 | H10: 1.06
A11: Gilat Satellite | B11: GILT | C11: 0.91 | D11: 650 | E11: -60 | F11: 0 | G11: 0.23 | H11: 0.91
A12: Comtech ⚠ distressed | B12: CMTL | C12: 1.05 | D12: 120 | E12: 250 | F12: 2.0833333 | G12: 0.21 | H12: 0.39685039
A13: — OPERATORS —
A14: Iridium | B14: IRDM | C14: 0.89 | D14: 2900 | E14: 1500 | F14: 0.51724138 | G14: 0.21 | H14: 0.63182375
A15: Viasat | B15: VSAT | C15: 1.05 | D15: 3800 | E15: 5700 | F15: 1.5 | G15: 0.21 | H15: 0.4805492
A16: SES | B16: SESG.PA | C16: 0.75 | D16: 3240 | E16: 3400 | F16: 1.0493827 | G16: 0.25 | H16: 0.41968912
A17: Globalstar ⚠ outlier | B17: GSAT | C17: 1.7 | D17: 3200 | E17: 300 | F17: 0.09375 | G17: 0.21 | H17: 1.5827757
A18: Rocket Lab ⚠ extreme | B18: RKLB | C18: 2 | D18: 20000 | E18: -400 | F18: 0 | G18: 0.21 | H18: 2
A20: UNLEVERED BETA STATISTICS (excl. ⚠)
A21: Ground segment median | H21: 0.985
A22: Ground segment mean | H22: 0.985
A23: Operators median | H23: 0.4805492
A24: All comps median | H24: 0.63182375
A25: All comps mean | H25: 0.70041241
A27: SELECTED UNLEVERED BETA | H27: 0.98
A28: Weighted toward ground median (0.99); business ~60% equipment + ~40% recurring service.
A31: STEP 2 — CAPM COST OF EQUITY (RMB-denominated)
A33: Input | B33: Value | C33: Source
A34: Risk-Free Rate (Rf) | B34: 0.0175 | C34: China 10Y CGB yield, Jun-2026 (1.72-1.75%)
A35: Equity Risk Premium (ERP) | B35: 0.0514 | C35: Damodaran Jan-2026: mature 4.23% + China country 0.91%
A36: Unlevered Beta (β_u) | B36: 0.98 | C36: Step 1
A37: Target D/E | B37: 0.05 | C37: Near-zero; all-equity pre-IPO, minimal post-IPO leverage
A38: Tax Rate | B38: 0.15 | C38: High-tech enterprise preferential (15% vs standard 25%)
A39: Re-levered Beta (β_L) | B39: 1.02165 | C39: β_u × [1 + (1−t) × D/E]
A41: CAPM Base Ke | B41: 0.07001281 | C41: Rf + β_L × ERP
A44: STEP 3 — ADDITIONAL RISK PREMIUMS
A45: CAPM underestimates Ke for pre-IPO small-caps. Standard add-ons (Duff & Phelps framework).
A47: Premium | B47: Low | C47: Base | D47: High | E47: Rationale
A48: Size Premium | B48: 0.025 | C48: 0.035 | D48: 0.045 | E48: EV ~¥40-70亿 = micro/small-cap; D&P 10th decile 3-5%
A49: Illiquidity / Pre-IPO | B49: 0.015 | C49: 0.025 | D49: 0.035 | E49: No public market; IPO filed not approved; 12-36mo lock-up
A50: Company-Specific Risk | B50: 0.01 | C50: 0.015 | D50: 0.025 | E50: Key-man, pre-profit, limited disclosure, revenue concentration
A51: Total Additional Premiums | B51: 0.05 | C51: 0.075 | D51: 0.105
...

Sheet Notes & Methodology
A1: NOTES, METHODOLOGY & DATA-CONFIDENCE LOG
B3: DATA SOURCES & CONFIDENCE
A4: • | B4: MCP institutional feed (S&P Global / Kensho) was NOT available this session — user lacks access. Per the comps skill, web search is not an institutional primary source; therefore all public-comp trading figures except 星图测控 & KSAT are CLAUDE ESTIMATES as of the Jan-2026 knowledge cutoff and MUST be verified against Bloomberg / FactSet / filings before any decision.
A5: • | B5: VETTED (higher confidence): 星图测控 (920116.BJ) financials and KSAT operating metrics come from the prior session's analyst-vetted web research (STCN, 36Kr, company & 北交所 disclosures).
A6: • | B6: ESTIMATE — VERIFY (lower confidence): Kratos, Gilat, Comtech, Iridium, Viasat, SES, Globalstar, Rocket Lab. The 2025 commercial-space equity rally made several caps (KTOS, RKLB, GSAT) highly volatile — multiples may be materially stale.
B7: FX ASSUMPTIONS (to convert comp table to USD mm)
A8: • | B8: USD/CNY 7.15 · USD/NOK 10.6 · EUR/USD 1.08. Comp-table multiples are currency-neutral ratios; only absolute size figures are FX-sensitive.
B9: KEY DEFINITIONS
A10: • | B10: Enterprise Value = Market Cap + Net Debt (negative net debt = net cash). EV/Revenue & EV/EBITDA use LTM/latest-FY. P/E = Market Cap / Net Income; shown 'n/m' where NI ≤ 0.
A11: • | B11: EBITDA for 星图测控 is estimated (~35% margin off disclosed ~29.5% net margin); company does not cleanly disclose EBITDA.
B12: WHY NOT A SINGLE MULTIPLE (the core analytical point)
A13: • | B13: 航天驭星 is a capacity-build infrastructure company: capex/asset base is front-loaded, revenue lags. EV/Sales on TODAY's sales overstates 'expensiveness' — a timing mismatch, not necessarily overvaluation. Hence five lenses.
A14: • | B14: Business is NOT one company: (1) recurring TT&C service [KSAT/operator-like, higher multiple], (2) project-based ground-station equipment [Kratos/Gilat-like, lower, lumpy multiple], (3) early 航天云 data [optionality]. A single blended multiple destroys this information → we split.
B15: HEADLINE FINDING
A16: • | B16: Current-sales methods (Method 1 ¥~20-46亿; Method 3 capacity ¥~22-43亿) sit below the ¥60-70亿 private mark. Forward-sales (Method 2, 2027E) now EXCEEDS the mark (~¥60-98亿 undiscounted) with volume-corrected estimates. Interpretation: with doubling-trend volumes, the unicorn valuation is now within or below the forward fair value range. Concluded today's fair value ¥48-72亿 — the funding mark sits at the lower end of the range.
B17: COMPARABILITY CAVEATS
A18: • | B18: 星图测控: ~73% special/defense revenue, mature, 北交所 micro-cap scarcity premium → P/S ~50x is an outlier, not a clean read-across to a private commercial-space name.
A19: • | B19: Satellite operators (IRDM/VSAT/SES/GSAT/RKLB) are vertically integrated and demand-side; used as a sector band, NOT pure comps. Comtech distressed & Rocket Lab extreme-growth → excluded from core percentile stats.
A20: • | B20: KSAT is the closest business analog (global ground-station network selling satellite passes) but is private (no trading multiple) and does not sell ground-station equipment to third parties the way 航天驭星 does.
B21: UNIT ECONOMICS (supporting tab)
A22: • | B22: Translated from the SaaS unit-economics frame to a capacity-infra frame: pass = usage unit, station = capacity/asset unit, satellite operator = customer, in-orbit life = contract life. Station-level ROIC & utilization are the BINDING metrics; LTV/CAC per satellite looks high (~14-21x) only because per-satellite onboarding cost is trivial — the real capital sits in network capex (Section A), so the two must be read together.
A23: • | B23: Operating-leverage bridge: at current low utilization the service network barely covers its depreciation (EBIT margin ~−7% to low-single-digits on the service line alone); the identical asset base swings to ~35% EBIT / ~49% EBITDA at full utilization. Pass-level incremental contribution ~87%. This is the mechanism behind the comps conclusion that the private mark is a forward/utilization bet.
B24: OPEN ITEMS TO VERIFY / IMPROVE
A25: • | B25: Replace all ESTIMATE comp figures with a live data pull. Confirm actual round stake %s (Method 4) and 航天驭星's annual ACTIVE (not cumulative) satellites served & true revenue split once the prospectus (招股书) is filed.
B27: WACC ANALYSIS (new tab)
A28: • | B28: Prior 20% discount rate replaced with WACC = 14.0% (base). Derived from: China 10Y CGB Rf 1.75%, Damodaran China ERP 5.14%, comp-derived unlevered β 0.98, plus size/illiquidity/company-specific premiums per Duff & Phelps framework.
A29: • | B29: Beta sources: KTOS 5Y monthly β 1.06 (Finbox), GILT 5Y monthly β 0.91 (Yahoo), IRDM 0.89 (Yahoo), VSAT ~1.05 (est.), SES ~0.75 (est.). Comtech (distressed), Globalstar (outlier), Rocket Lab (extreme growth) excluded from core stats.
A30: • | B30: Impact: Volume correction (32万→48万 passes) and 2027E service revenue upgrade (¥500M→¥900M) combined with WACC 14.0% yield Method 2b PV ~¥76亿. Concluded fair value updated to ¥48-72亿 (was ¥38-58亿). Funding mark now sits WITHIN the fair value range rather than above it.
B32: INTERNATIONAL PRICING BENCHMARKS (new tab)
A33: • | B33: Per-pass pricing assumption (¥750 base) now anchored to four independent benchmarks: (1) AWS Ground Station published rates — S-band narrowband $3/min reserved, $10/min on-demand (source: aws.amazon.com/ground-station/pricing); (2) KSAT 2024 implied — NOK 2,236M revenue (~$210M), 1.5M+ annual passes → $98-140/pass (source: Space Norway AR 2024); (3) China per-satellite annual fee — industry benchmark ¥60-70万/sat/yr from 未来航天 research → ¥600-700/pass at 1,000 passes/yr; (4) Frank Rayal GSaaS market analysis — full-service TT&C $69-300/pass depending on coverage tier.
A34: • | B34: 航天驭星 sits in Tier ③ "Full-service TT&C" ($69-138/pass, ¥500-1,000/pass) — owns 60+ stations, provides mission planning/operations, not raw antenna rental. ¥750/pass ($103) aligns with KSAT-adjusted implied ($98/pass) within 5%.
A35: • | B35: Remaining gap: no direct observation of contracted pricing from 航天驭星. ¥750 upgraded from "UNSUPPORTED" to "SUPPORTED BY BENCHMARKS" but still requires confirmation from prospectus filing.
A36: • | B36: Key data points used: KSAT Q1 2025 revenue NOK 556M (annualized ~NOK 2.2B); KSAT 2023 passes >1.5M; Leaf Space 5,000+ passes/month for 60+ sats; AWS GS narrowband $3-10/min, wideband $10-22/min; 星图测控 2024 revenue ¥288M (testing/control management ¥197M).
